Traceback (most recent call last):
  File "/home/lorenzf/git/data-science-practical-approach/venv/lib/python3.8/site-packages/jupyter_cache/executors/utils.py", line 51, in single_nb_execution
    executenb(
  File "/home/lorenzf/git/data-science-practical-approach/venv/lib/python3.8/site-packages/nbclient/client.py", line 1117, in execute
    return NotebookClient(nb=nb, resources=resources, km=km, **kwargs).execute()
  File "/home/lorenzf/git/data-science-practical-approach/venv/lib/python3.8/site-packages/nbclient/util.py", line 78, in wrapped
    return just_run(coro(*args, **kwargs))
  File "/home/lorenzf/git/data-science-practical-approach/venv/lib/python3.8/site-packages/nbclient/util.py", line 57, in just_run
    return loop.run_until_complete(coro)
  File "/usr/lib/python3.8/asyncio/base_events.py", line 616, in run_until_complete
    return future.result()
  File "/home/lorenzf/git/data-science-practical-approach/venv/lib/python3.8/site-packages/nbclient/client.py", line 558, in async_execute
    await self.async_execute_cell(
  File "/home/lorenzf/git/data-science-practical-approach/venv/lib/python3.8/site-packages/nbclient/client.py", line 862, in async_execute_cell
    self._check_raise_for_error(cell, exec_reply)
  File "/home/lorenzf/git/data-science-practical-approach/venv/lib/python3.8/site-packages/nbclient/client.py", line 765, in _check_raise_for_error
    raise CellExecutionError.from_cell_and_msg(cell, exec_reply_content)
nbclient.exceptions.CellExecutionError: An error occurred while executing the following cell:
------------------
oe.transform(raw_material_df)
------------------

[0;31m---------------------------------------------------------------------------[0m
[0;31mValueError[0m                                Traceback (most recent call last)
[0;32m/tmp/ipykernel_5333/2646731538.py[0m in [0;36m<module>[0;34m[0m
[0;32m----> 1[0;31m [0moe[0m[0;34m.[0m[0mtransform[0m[0;34m([0m[0mraw_material_df[0m[0;34m)[0m[0;34m[0m[0;34m[0m[0m
[0m
[0;32m~/git/data-science-practical-approach/venv/lib/python3.8/site-packages/sklearn/preprocessing/_encoders.py[0m in [0;36mtransform[0;34m(self, X)[0m
[1;32m    803[0m             [0mTransformed[0m [0minput[0m[0;34m.[0m[0;34m[0m[0;34m[0m[0m
[1;32m    804[0m         """
[0;32m--> 805[0;31m         [0mX_int[0m[0;34m,[0m [0mX_mask[0m [0;34m=[0m [0mself[0m[0;34m.[0m[0m_transform[0m[0;34m([0m[0mX[0m[0;34m,[0m [0mhandle_unknown[0m[0;34m=[0m[0mself[0m[0;34m.[0m[0mhandle_unknown[0m[0;34m)[0m[0;34m[0m[0;34m[0m[0m
[0m[1;32m    806[0m         [0mX_trans[0m [0;34m=[0m [0mX_int[0m[0;34m.[0m[0mastype[0m[0;34m([0m[0mself[0m[0;34m.[0m[0mdtype[0m[0;34m,[0m [0mcopy[0m[0;34m=[0m[0;32mFalse[0m[0;34m)[0m[0;34m[0m[0;34m[0m[0m
[1;32m    807[0m [0;34m[0m[0m

[0;32m~/git/data-science-practical-approach/venv/lib/python3.8/site-packages/sklearn/preprocessing/_encoders.py[0m in [0;36m_transform[0;34m(self, X, handle_unknown, force_all_finite)[0m
[1;32m    118[0m [0;34m[0m[0m
[1;32m    119[0m         [0;32mif[0m [0mn_features[0m [0;34m!=[0m [0mlen[0m[0;34m([0m[0mself[0m[0;34m.[0m[0mcategories_[0m[0;34m)[0m[0;34m:[0m[0;34m[0m[0;34m[0m[0m
[0;32m--> 120[0;31m             raise ValueError(
[0m[1;32m    121[0m                 [0;34m"The number of features in X is different to the number of "[0m[0;34m[0m[0;34m[0m[0m
[1;32m    122[0m                 [0;34m"features of the fitted data. The fitted data had {} features "[0m[0;34m[0m[0;34m[0m[0m

[0;31mValueError[0m: The number of features in X is different to the number of features of the fitted data. The fitted data had 2 features and the X has 9 features.
ValueError: The number of features in X is different to the number of features of the fitted data. The fitted data had 2 features and the X has 9 features.

