Traceback (most recent call last):
  File "/home/lorenzf/git/data-science-practical-approach/venv/lib/python3.8/site-packages/jupyter_cache/executors/utils.py", line 51, in single_nb_execution
    executenb(
  File "/home/lorenzf/git/data-science-practical-approach/venv/lib/python3.8/site-packages/nbclient/client.py", line 1117, in execute
    return NotebookClient(nb=nb, resources=resources, km=km, **kwargs).execute()
  File "/home/lorenzf/git/data-science-practical-approach/venv/lib/python3.8/site-packages/nbclient/util.py", line 78, in wrapped
    return just_run(coro(*args, **kwargs))
  File "/home/lorenzf/git/data-science-practical-approach/venv/lib/python3.8/site-packages/nbclient/util.py", line 57, in just_run
    return loop.run_until_complete(coro)
  File "/usr/lib/python3.8/asyncio/base_events.py", line 616, in run_until_complete
    return future.result()
  File "/home/lorenzf/git/data-science-practical-approach/venv/lib/python3.8/site-packages/nbclient/client.py", line 558, in async_execute
    await self.async_execute_cell(
  File "/home/lorenzf/git/data-science-practical-approach/venv/lib/python3.8/site-packages/nbclient/client.py", line 862, in async_execute_cell
    self._check_raise_for_error(cell, exec_reply)
  File "/home/lorenzf/git/data-science-practical-approach/venv/lib/python3.8/site-packages/nbclient/client.py", line 765, in _check_raise_for_error
    raise CellExecutionError.from_cell_and_msg(cell, exec_reply_content)
nbclient.exceptions.CellExecutionError: An error occurred while executing the following cell:
------------------
statistics.median(titanic_df['embark_town'])
------------------

[0;31m---------------------------------------------------------------------------[0m
[0;31mTypeError[0m                                 Traceback (most recent call last)
[0;32m/tmp/ipykernel_11541/1735617235.py[0m in [0;36m<module>[0;34m[0m
[0;32m----> 1[0;31m [0mstatistics[0m[0;34m.[0m[0mmedian[0m[0;34m([0m[0mtitanic_df[0m[0;34m[[0m[0;34m'embark_town'[0m[0;34m][0m[0;34m)[0m[0;34m[0m[0;34m[0m[0m
[0m
[0;32m/usr/lib/python3.8/statistics.py[0m in [0;36mmedian[0;34m(data)[0m
[1;32m    425[0m [0;34m[0m[0m
[1;32m    426[0m     """
[0;32m--> 427[0;31m     [0mdata[0m [0;34m=[0m [0msorted[0m[0;34m([0m[0mdata[0m[0;34m)[0m[0;34m[0m[0;34m[0m[0m
[0m[1;32m    428[0m     [0mn[0m [0;34m=[0m [0mlen[0m[0;34m([0m[0mdata[0m[0;34m)[0m[0;34m[0m[0;34m[0m[0m
[1;32m    429[0m     [0;32mif[0m [0mn[0m [0;34m==[0m [0;36m0[0m[0;34m:[0m[0;34m[0m[0;34m[0m[0m

[0;31mTypeError[0m: '<' not supported between instances of 'float' and 'str'
TypeError: '<' not supported between instances of 'float' and 'str'

